Workbook

Sheet data (1)
A1: DR_Dat | B1: DR_Tim | C1: DR_NChk | D1: DR_NDoc | E1: DR_Apt | F1: DR_Kkm | G1: DR_TDoc | H1: DR_TPay | I1: DR_CDrugs | J1: DR_NDrugs | K1: DR_Suppl | L1: DR_Prod | M1: DR_Kol | N1: DR_CZak | O1: DR_CRoz | P1: DR_SDisc | Q1: DR_CDisc | R1: DR_BCDisc | S1: DR_TabEmpl | T1: DR_VZak | U1: DR_Pos | V1: DR_Revenue
A2: 44774 | B2: 0.33770833 | C2: 1272 | D2: 13002561 | E2: 13 | F2: 22589 | G2: Розничная реализация | H2: 18 | I2: 144734 | J2: ГАСТАЛ №12 ТАБ. Д/РАСС. | K2: Пульс | L2: TEVA Pharvaceutical Industries Ltd | M2: 1 | N2: 196.71 | O2: 270 | P2: 0 | Q2: NULL | R2: NULL | S2: 29 | T2: 1 | U2: 1 | V2: =O2*M2 -> 270
A3: 44774 | B3: 0.36033565 | C3: 1273 | D3: 13002561 | E3: 13 | F3: 22589 | G3: Розничная реализация | H3: 15 | I3: 69661 | J3: ТОБРОПТ 0,3% 5МЛ. №1 ГЛ.КАПЛИ ФЛ./КАП. /РОМФАРМ/ | K3: Пульс | L3: РОМФАРМ КОМПАНИ ( ROMPHARM ) | M3: 1 | N3: 106.21 | O3: 127 | P3: 6 | Q3: 9 | R3: 200010004357 | S3: 29 | T3: 1 | U3: 1 | V3: =O3*M3 -> 127
A4: 44774 | B4: 0.37196759 | C4: 1274 | D4: 13002561 | E4: 13 | F4: 22589 | G4: Розничная реализация | H4: 18 | I4: 190635 | J4: ЭЛИКВИС 5МГ. №60 ТАБ. П/П/О /ПФАЙЗЕР/БРИСТОЛ-МАЙЕРС/ | K4: ГРАНД КАПИТАЛ СМОЛЕНСК ООО ФК | L4: Пфайзер | M4: 1 | N4: 2320.99 | O4: 2563 | P4: 76 | Q4: 9 | R4: 200010018491 | S4: 29 | T4: 1 | U4: 1 | V4: =O4*M4 -> 2563
A5: 44774 | B5: 0.37546296 | C5: 1275 | D5: 13002561 | E5: 13 | F5: 22589 | G5: Розничная реализация | H5: 18 | I5: 276370 | J5: АРБИДОЛ МАКСИМУМ 200МГ. №10 КАПС. /ОТИСИФАРМ/ФАРМСТАНДАРТ/ | K5: Пульс | L5: ОТИСИФАРМ ПАО | M5: 1 | N5: 445.39 | O5: 541 | P5: 0 | Q5: NULL | R5: NULL | S5: 29 | T5: 1 | U5: 1 | V5: =O5*M5 -> 541 | X5: =MIN(A:A) -> 44774
A6: 44774 | B6: 0.37783565 | C6: 1276 | D6: 13002561 | E6: 13 | F6: 22589 | G6: Розничная реализация | H6: 15 | I6: 2303 | J6: ЭНАМ 2,5МГ. №20 ТАБ. /Д-Р РЕДДИ/ | K6: Протек | L6: Д-р Редди с Лабораторис Лтд / Dr.REDDY's | M6: 1 | N6: 18.04 | O6: 22 | P6: 1 | Q6: 9 | R6: 200010000734 | S6: 29 | T6: 1 | U6: 5 | V6: =O6*M6 -> 22 | X6: =MAX(A:A) -> 44778
A7: 44774 | B7: 0.37783565 | C7: 1276 | D7: 13002561 | E7: 13 | F7: 22589 | G7: Розничная реализация | H7: 15 | I7: 2303 | J7: ЭНАМ 2,5МГ. №20 ТАБ. /Д-Р РЕДДИ/ | K7: Протек | L7: Д-р Редди с Лабораторис Лтд / Dr.REDDY's | M7: 1 | N7: 18.04 | O7: 22 | P7: 1 | Q7: 9 | R7: 200010000734 | S7: 29 | T7: 1 | U7: 6 | V7: =O7*M7 -> 22
A8: 44774 | B8: 0.37783565 | C8: 1276 | D8: 13002561 | E8: 13 | F8: 22589 | G8: Розничная реализация | H8: 15 | I8: 338588 | J8: КЛОПИДОГРЕЛ-СЗ 75МГ. №28 ТАБ. П/П/О /СЕВЕРНАЯ ЗВЕЗДА/ | K8: Пульс | L8: Северная Звезда | M8: 1 | N8: 383.7 | O8: 475 | P8: 23 | Q8: 9 | R8: 200010000734 | S8: 29 | T8: 1 | U8: 3 | V8: =O8*M8 -> 475
A9: 44774 | B9: 0.37783565 | C9: 1276 | D9: 13002561 | E9: 13 | F9: 22589 | G9: Розничная реализация | H9: 15 | I9: 397616 | J9: КО-ВАМЛОСЕТ 5МГ.+160МГ.+12,5МГ. №30 ТАБ. П/П/О | K9: Протек | L9: КРКА-Рус ООО (KRKA ) | M9: 1 | N9: 536.82 | O9: 693 | P9: 48 | Q9: 9 | R9: 200010000734 | S9: 29 | T9: 1 | U9: 4 | V9: =O9*M9 -> 693
A10: 44774 | B10: 0.37783565 | C10: 1276 | D10: 13002561 | E10: 13 | F10: 22589 | G10: Розничная реализация | H10: 15 | I10: 338492 | J10: АТОРВАСТАТИН-СЗ 20МГ. №60 ТАБ. П/П/О /СЕВЕРНАЯ ЗВЕЗДА/ | K10: Протек | L10: Северная Звезда | M10: 1 | N10: 334.29 | O10: 418 | P10: 20 | Q10: 9 | R10: 200010000734 | S10: 29 | T10: 1 | U10: 1 | V10: =O10*M10 -> 418
A11: 44774 | B11: 0.37783565 | C11: 1276 | D11: 13002561 | E11: 13 | F11: 22589 | G11: Розничная реализация | H11: 15 | I11: 338479 | J11: АТОРВАСТАТИН-СЗ 40МГ. №30 ТАБ. П/П/О /СЕВЕРНАЯ ЗВЕЗДА/ | K11: Пульс | L11: Северная Звезда | M11: 1 | N11: 282.52 | O11: 340 | P11: 17 | Q11: 9 | R11: 200010000734 | S11: 29 | T11: 1 | U11: 2 | V11: =O11*M11 -> 340
A12: 44774 | B12: 0.37849537 | C12: 1277 | D12: 13002561 | E12: 13 | F12: 22589 | G12: Розничная реализация | H12: 18 | I12: 122156 | J12: КСИМЕЛИН ЭКСТРА 84МКГ/ДОЗА+70МКГ/ДОЗА 10МЛ. №1 НАЗАЛ.СПРЕЙ ДОЗИР. ФЛ. | K12: Пульс | L12: ТАКЕДА ФАРМАСЬЮТИКАЛ КОМПАНИ ЛИМИТЕД | M12: 1 | N12: 210.25 | O12: 284 | P12: 0 | Q12: NULL | R12: NULL | S12: 29 | T12: 1 | U12: 1 | V12: =O12*M12 -> 284
A13: 44774 | B13: 0.38320602 | C13: 1278 | D13: 13002561 | E13: 13 | F13: 22589 | G13: Розничная реализация | H13: 15 | I13: 608487 | J13: NF ВАТА ХИРУРГ. СТЕР. 100Г. /НЬЮФАРМ/ | K13: Фармкомплект ООО | L13: НьюФарм | M13: 1 | N13: 43.29 | O13: 71 | P13: 7 | Q13: 9 | R13: 200010001758 | S13: 29 | T13: 1 | U13: 1 | V13: =O13*M13 -> 71
A14: 44774 | B14: 0.38320602 | C14: 1278 | D14: 13002561 | E14: 13 | F14: 22589 | G14: Розничная реализация | H14: 15 | I14: 528004 | J14: СТОПСЕПТ ПЛЮС 90% 100МЛ. ДЕЗ.СР-ВО ФЛ. | K14: Авеста | L14: ГИППОКРАТ ООО | M14: 1 | N14: 35.52 | O14: 58 | P14: 5 | Q14: 9 | R14: 200010001758 | S14: 29 | T14: 1 | U14: 2 | V14: =O14*M14 -> 58
A15: 44774 | B15: 0.38756944 | C15: 1279 | D15: 13002561 | E15: 13 | F15: 22589 | G15: Розничная реализация | H15: 15 | I15: 443174 | J15: ПАСКАЛЬ ШПРИЦ 3-Х КОМП. 2МЛ. С ИГЛОЙ 23G 0,6Х30ММ. №10 [PASCAL] | K15: Катрен г.Химки | L15: ПАСКАЛЬ МЕДИКАЛ | M15: 1 | N15: 65.13 | O15: 103 | P15: 0 | Q15: NULL | R15: NULL | S15: 29 | T15: 1 | U15: 1 | V15: =O15*M15 -> 103
A16: 44774 | B16: 0.44326389 | C16: 1294 | D16: 13002561 | E16: 13 | F16: 22589 | G16: Розничная реализация | H16: 18 | I16: 443174 | J16: ПАСКАЛЬ ШПРИЦ 3-Х КОМП. 2МЛ. С ИГЛОЙ 23G 0,6Х30ММ. №10 [PASCAL] | K16: Катрен г.Химки | L16: ПАСКАЛЬ МЕДИКАЛ | M16: 1 | N16: 65.13 | O16: 103 | P16: 0 | Q16: NULL | R16: NULL | S16: 29 | T16: 1 | U16: 3 | V16: =O16*M16 -> 103
A17: 44774 | B17: 0.39586806 | C17: 1280 | D17: 13002561 | E17: 13 | F17: 22589 | G17: Розничная реализация | H17: 15 | I17: 21372 | J17: КЛОТРИМАЗОЛ 1% 20Г. КРЕМ Д/НАРУЖ.ПРИМ. ТУБА /ХИПЕРИОН/РУМЫНИЯ/ | K17: Пульс | L17: HYPERION SA (ХИПЕРИОН ) | M17: 1 | N17: 86.28 | O17: 123 | P17: 0 | Q17: NULL | R17: NULL | S17: 29 | T17: 1 | U17: 1 | V17: =O17*M17 -> 123
A18: 44774 | B18: 0.39586806 | C18: 1280 | D18: 13002561 | E18: 13 | F18: 22589 | G18: Розничная реализация | H18: 15 | I18: 365627 | J18: РИНОНОРМ-ТЕВА 0,1% 140МКГ/ДОЗА 20МЛ. НАЗАЛ.СПРЕЙ ФЛ. /ТЕВА/ | K18: ГРАНД КАПИТАЛ СМОЛЕНСК ООО ФК | L18: ТЕВА ЧЕШСКОЕ ПРЕДПРИЯТИЕ | M18: 1 | N18: 78.24 | O18: 96 | P18: 0 | Q18: NULL | R18: NULL | S18: 29 | T18: 1 | U18: 2 | V18: =O18*M18 -> 96
A19: 44774 | B19: 0.68071759 | C19: 1373 | D19: 13002561 | E19: 13 | F19: 22589 | G19: Розничная реализация | H19: 18 | I19: 365627 | J19: РИНОНОРМ-ТЕВА 0,1% 140МКГ/ДОЗА 20МЛ. НАЗАЛ.СПРЕЙ ФЛ. /ТЕВА/ | K19: ГРАНД КАПИТАЛ СМОЛЕНСК ООО ФК | L19: ТЕВА ЧЕШСКОЕ ПРЕДПРИЯТИЕ | M19: 1 | N19: 78.24 | O19: 96 | P19: 0 | Q19: NULL | R19: NULL | S19: 29 | T19: 1 | U19: 1 | V19: =O19*M19 -> 96
A20: 44774 | B20: 0.40825231 | C20: 1281 | D20: 13002561 | E20: 13 | F20: 22589 | G20: Розничная реализация | H20: 15 | I20: 12625 | J20: ДЮФАЛАК 667МГ/МЛ. 500МЛ. СИРОП ФЛ. +МЕРН.СТАКАН /ЭББОТТ/СОЛВЕЙ/ | K20: Арал плюс | L20: Abbott Japan Co ( ЭББОТТ ) | M20: 1 | N20: 455.9 | O20: 553 | P20: 16 | Q20: 9 | R20: 200010001617 | S20: 29 | T20: 1 | U20: 1 | V20: =O20*M20 -> 553
A21: 44774 | B21: 0.41150463 | C21: 1282 | D21: 13002561 | E21: 13 | F21: 22589 | G21: Розничная реализация | H21: 18 | I21: 67565 | J21: ГЕЛАДРИНК ФОРТЕ ПОР. Д/ПРИЕМА ВНУТРЬ АПЕЛЬСИН 420Г. БАНКА | K21: ВИТТА КОМПАНИ ООО | L21: ОРЛИНГ | M21: 1 | N21: 3638.1 | O21: 4985 | P21: 498 | Q21: 9 | R21: 200010004830 | S21: 29 | T21: 1 | U21: 1 | V21: =O21*M21 -> 4985
A22: 44774 | B22: 0.41150463 | C22: 1282 | D22: 13002561 | E22: 13 | F22: 22589 | G22: Розничная реализация | H22: 18 | I22: 507949 | J22: ПИРАЦЕТАМ 200МГ. №60 ТАБ. П/П/О /ОБНОВЛЕНИЕ/ | K22: ГК Надежда Фарм | L22: ОБНОВЛЕНИЕ ПФК | M22: 1 | N22: 60.22 | O22: 73 | P22: 3 | Q22: 9 | R22: 200010004830 | S22: 29 | T22: 1 | U22: 2 | V22: =O22*M22 -> 73
A23: 44774 | B23: 0.4140162 | C23: 1283 | D23: 13002561 | E23: 13 | F23: 22589 | G23: Розничная реализация | H23: 15 | I23: 461654 | J23: МАГНЕЛИС В6 №120 ТАБ. П/О | K23: Катрен г.Химки | L23: ФАРМСТАНДАРТ УФАВИТА | M23: 1 | N23: 677.2 | O23: 779 | P23: 54 | Q23: 9 | R23: 200010020913 | S23: 29 | T23: 1 | U23: 2 | V23: =O23*M23 -> 779
A24: 44774 | B24: 0.4140162 | C24: 1283 | D24: 13002561 | E24: 13 | F24: 22589 | G24: Розничная реализация | H24: 15 | I24: 7697 | J24: МЕЗИМ-ФОРТЕ №80 ТАБ. П/О /БЕРЛИН-ХЕМИ/ | K24: Пульс | L24: Берлин-Хеми АГ/Менарини Групп (Menarini ) | M24: 1 | N24: 248.34 | O24: 302 | P24: 15 | Q24: 9 | R24: 200010020913 | S24: 29 | T24: 1 | U24: 3 | V24: =O24*M24 -> 302
A25: 44774 | B25: 0.4140162 | C25: 1283 | D25: 13002561 | E25: 13 | F25: 22589 | G25: Розничная реализация | H25: 15 | I25: 340968 | J25: КАЛЬЦИЙ Д3 НИКОМЕД 500МГ.+200МЕ №60 КЛУБНИКА+АРБУЗ ТАБ.ЖЕВ. | K25: Пульс | L25: ТАКЕДА ФАРМАСЬЮТИКАЛ КОМПАНИ ЛИМИТЕД | M25: 1 | N25: 403.68 | O25: 533 | P25: 37 | Q25: 9 | R25: 200010020913 | S25: 29 | T25: 1 | U25: 1 | V25: =O25*M25 -> 533
A26: 44774 | B26: 0.41548611 | C26: 1284 | D26: 13002561 | E26: 13 | F26: 22589 | G26: Розничная реализация | H26: 15 | I26: 530607 | J26: ЭКСПРЕСС-ТЕСТ НА А/ТЕЛА COVID-19 LGG/LGM | K26: Арал плюс | L26: ИМТЭК ООО | M26: 2 | N26: 619.88 | O26: 862 | P26: 172 | Q26: 9 | R26: 200010017394 | S26: 29 | T26: 1 | U26: 1 | V26: =O26*M26 -> 1724
A27: 44774 | B27: 0.41795139 | C27: 1285 | D27: 13002561 | E27: 13 | F27: 22589 | G27: Розничная реализация | H27: 18 | I27: 330172 | J27: БОБС ЛЕДЕНЦЫ Д/ГОРЛА 35Г. ЭКСТРА МЕНТОЛ №10 | K27: Протек | L27: МАК-ИВАНОВО | M27: 1 | N27: 23.98 | O27: 39 | P27: 0 | Q27: NULL | R27: NULL | S27: 29 | T27: 1 | U27: 1 | V27: =O27*M27 -> 39
A28: 44774 | B28: 0.41947917 | C28: 1286 | D28: 13002561 | E28: 13 | F28: 22589 | G28: Розничная реализация | H28: 18 | I28: 393315 | J28: ЦИТРАМОН П №10 ТАБ. /ФАРМСТАНДАРТ/ | K28: Катрен г.Химки | L28: ФАРМСТАНДАРТ ЛЕКСРЕДСТВА ОАО | M28: 1 | N28: 16.21 | O28: 25 | P28: 0 | Q28: NULL | R28: NULL | S28: 29 | T28: 1 | U28: 1 | V28: =O28*M28 -> 25
A29: 44774 | B29: 0.41947917 | C29: 1286 | D29: 13002561 | E29: 13 | F29: 22589 | G29: Розничная реализация | H29: 18 | I29: 393315 | J29: ЦИТРАМОН П №10 ТАБ. /ФАРМСТАНДАРТ/ | K29: Катрен г.Химки | L29: ФАРМСТАНДАРТ ЛЕКСРЕДСТВА ОАО | M29: 1 | N29: 16.21 | O29: 25 | P29: 0 | Q29: NULL | R29: NULL | S29: 29 | T29: 1 | U29: 2 | V29: =O29*M29 -> 25
A30: 44774 | B30: 0.62164352 | C30: 1362 | D30: 13002561 | E30: 13 | F30: 22589 | G30: Розничная реализация | H30: 18 | I30: 393315 | J30: ЦИТРАМОН П №10 ТАБ. /ФАРМСТАНДАРТ/ | K30: Катрен г.Химки | L30: ФАРМСТАНДАРТ ЛЕКСРЕДСТВА ОАО | M30: 1 | N30: 16.21 | O30: 25 | P30: 0 | Q30: NULL | R30: NULL | S30: 29 | T30: 1 | U30: 3 | V30: =O30*M30 -> 25
A31: 44774 | B31: 0.42930556 | C31: 1287 | D31: 13002561 | E31: 13 | F31: 22589 | G31: Розничная реализация | H31: 18 | I31: 377588 | J31: ТИЗИН КЛАССИК 0,1% 10МЛ. НАЗАЛ.СПРЕЙ ФЛ. /ДЖОНСОН/ | K31: Катрен г.Химки | L31: ДЕЛЬФАРМ ОРЛЕАН ( DELPHARM ) | M31: 1 | N31: 84.17 | O31: 100 | P31: 41.09 | Q31: 925 | R31: 200000000492 | S31: 29 | T31: 1 | U31: 3 | V31: =O31*M31 -> 100
A32: 44774 | B32: 0.42930556 | C32: 1287 | D32: 13002561 | E32: 13 | F32: 22589 | G32: Розничная реализация | H32: 18 | I32: 297336 | J32: ЛАКОМКА ПОМАДА ГИГИЕН. ЯГОДНЫЙ МИКС 2,8Г. /АВАНТА/ | K32: Протек | L32: АВАНТА ОАО | M32: 1 | N32: 45.17 | O32: 74 | P32: 30.41 | Q32: 925 | R32: 200000000492 | S32: 29 | T32: 1 | U32: 1 | V32: =O32*M32 -> 74
A33: 44774 | B33: 0.42930556 | C33: 1287 | D33: 13002561 | E33: 13 | F33: 22589 | G33: Розничная реализация | H33: 18 | I33: 2302 | J33: ОМЕЗ 20МГ. №30 КАПС. /Д-Р РЕДДИ/ | K33: ВИТТА КОМПАНИ ООО | L33: ДОКТОР РЕДДИ С ЛАБ / Dr. REDDY's ) | M33: 1 | N33: 148.28 | O33: 174 | P33: 71.5 | Q33: 925 | R33: 200000000492 | S33: 29 | T33: 1 | U33: 2 | V33: =O33*M33 -> 174
A34: 44774 | B34: 0.43451389 | C34: 1288 | D34: 13002561 | E34: 13 | F34: 22589 | G34: Розничная реализация | H34: 15 | I34: 23396 | J34: ЭВКАЛИПТ М №24 ПАСТИЛКИ | K34: ООО "Акцентмед" | L34: ДР.АУФДЕРМАУР АГ | M34: 2 | N34: 248.26 | O34: 336 | P34: 0 | Q34: NULL | R34: NULL | S34: 29 | T34: 1 | U34: 1 | V34: =O34*M34 -> 672
A35: 44774 | B35: 0.43633102 | C35: 1289 | D35: 13002561 | E35: 13 | F35: 22589 | G35: Розничная реализация | H35: 15 | I35: 143150 | J35: АЗАРГА 10МГ/МЛ.+5МГ/МЛ. 5МЛ. №1 ГЛ.КАПЛИ ФЛ./КАП. | K35: ВИТТА КОМПАНИ ООО | L35: АЛКОН Куврер н.в. (ALCON ) | M35: 1 | N35: 1042.25 | O35: 1314 | P35: 91 | Q35: 9 | R35: 200010000065 | S35: 29 | T35: 1 | U35: 1 | V35: =O35*M35 -> 1314
A36: 44774 | B36: 0.43633102 | C36: 1289 | D36: 13002561 | E36: 13 | F36: 22589 | G36: Розничная реализация | H36: 15 | I36: 263189 | J36: ТРАВАТАН 0,004% 2,5МЛ. №3 ГЛ.КАПЛИ ФЛ./КАП. | K36: Катрен г.Химки | L36: ALCON COUVREUR (АЛКОН ) | M36: 1 | N36: 1576.65 | O36: 1971 | P36: 137 | Q36: 9 | R36: 200010000065 | S36: 29 | T36: 1 | U36: 5 | V36: =O36*M36 -> 1971
A37: 44774 | B37: 0.43633102 | C37: 1289 | D37: 13002561 | E37: 13 | F37: 22589 | G37: Розничная реализация | H37: 15 | I37: 519407 | J37: ЙОДА 5% 10МЛ. СПИРТ. Р-Р ФЛ. /ЯРОСЛАВСКАЯ ФФ/ | K37: Катрен г.Химки | L37: ЯРОСЛАВСКАЯ ФАРМ. ФАБРИКА | M37: 1 | N37: 34.25 | O37: 53 | P37: 3 | Q37: 9 | R37: 200010000065 | S37: 29 | T37: 1 | U37: 2 | V37: =O37*M37 -> 53
A38: 44774 | B38: 0.43633102 | C38: 1289 | D38: 13002561 | E38: 13 | F38: 22589 | G38: Розничная реализация | H38: 15 | I38: 345211 | J38: ОМЕПРАЗОЛ 20МГ. №30 КАПС. /ПРОИЗВОДСТВО МЕДИКАМЕНТОВ/ | K38: ГРАНД КАПИТАЛ СМОЛЕНСК ООО ФК | L38: ПРОИЗВОДСТВО МЕДИКАМЕНТОВ ООО | M38: 1 | N38: 25.28 | O38: 30 | P38: 1 | Q38: 9 | R38: 200010000065 | S38: 29 | T38: 1 | U38: 3 | V38: =O38*M38 -> 30
A39: 44774 | B39: 0.47800926 | C39: 1307 | D39: 13002561 | E39: 13 | F39: 22589 | G39: Розничная реализация | H39: 18 | I39: 345211 | J39: ОМЕПРАЗОЛ 20МГ. №30 КАПС. /ПРОИЗВОДСТВО МЕДИКАМЕНТОВ/ | K39: ГРАНД КАПИТАЛ СМОЛЕНСК ООО ФК | L39: ПРОИЗВОДСТВО МЕДИКАМЕНТОВ ООО | M39: 1 | N39: 25.28 | O39: 30 | P39: 1 | Q39: 9 | R39: 200010000452 | S39: 29 | T39: 1 | U39: 1 | V39: =O39*M39 -> 30
A40: 44774 | B40: 0.50565972 | C40: 1319 | D40: 13002561 | E40: 13 | F40: 22589 | G40: Розничная реализация | H40: 18 | I40: 345211 | J40: ОМЕПРАЗОЛ 20МГ. №30 КАПС. /ПРОИЗВОДСТВО МЕДИКАМЕНТОВ/ | K40: ГРАНД КАПИТАЛ СМОЛЕНСК ООО ФК | L40: ПРОИЗВОДСТВО МЕДИКАМЕНТОВ ООО | M40: 1 | N40: 25.28 | O40: 30 | P40: 1 | Q40: 9 | R40: 200010015482 | S40: 29 | T40: 1 | U40: 3 | V40: =O40*M40 -> 30
...

Sheet Лист11
A3: Названия строк | B3: Количество по полю ABC-XYZ
A4: AAAZ | B4: 176
A5: AABZ | B5: 6
A6: ABAZ | B6: 83
A7: ABBZ | B7: 59
A8: ACAZ | B8: 70
A9: ACBZ | B9: 29
A10: ACCZ | B10: 29
A11: BAAZ | B11: 98
A12: BABZ | B12: 5
A13: BBBZ | B13: 73
A14: BCBZ | B14: 37
A15: BCCZ | B15: 29
... A23: Общий итог | B23: 803

Sheet ABC
A1: Название | B1: Кол-во продаж | C1: доля | D1: кумулята | E1: тир | F1: Сумма продаж | G1: доля | H1: кумулята | I1: тир | J1: М. обор | K1: доля | L1: кумулята | M1: тир | N1: ABC | O1: var | P1: XYZ | Q1: ABC-XYZ
A2: ЛЕЙКОПЛАСТЫРЬ БАКТЕР. 2,5Х7,2 №1 /ВЕРОФАРМ/ | B2: 68 | C2: 0.04 | D2: 0.04 | E2: A | F2: 272 | G2: 0.00073894542 | H2: 0.8596827 | I2: B | J2: 408 | K2: =J2/SUM(J:J) -> 0.042265927 | L2: =K2 -> 0.042265927 | M2: =IF(L2<0.8,"A",IF(L2<0.95,"B","C")) -> A | N2: =E2&I2&M2 -> ABA | O2: =VLOOKUP(A2,XYZ!A1:G804,2,FALSE) -> 0.89693828 | P2: =IF(O2<0.1,"A",IF(O2<0.25,"Y","Z")) -> Z | Q2: =N2&P2 -> ABAZ
A3: НАФТИЗИН 0,1% 15МЛ. НАЗАЛ.КАПЛИ ФЛ./КАП. /СЛАВЯНСКАЯ АПТЕКА/ | B3: 35 | C3: 0.02 | D3: 0.06 | E3: A | F3: 280 | G3: 0.00076067911 | H3: 0.84995415 | I3: B | J3: 210 | K3: =J3/SUM(J:J) -> 0.021754521 | L3: =K3+L2 -> 0.064020449 | M3: =IF(L3<0.8,"A",IF(L3<0.95,"B","C")) -> A | N3: =E3&I3&M3 -> ABA | O3: =VLOOKUP(A3,XYZ!A2:G805,2,FALSE) -> 0.69985421 | P3: =IF(O3<0.1,"A",IF(O3<0.25,"Y","Z")) -> Z | Q3: =N3&P3 -> ABAZ
A4: ПАКЕТ | B4: 26 | C4: 0.02 | D4: 0.08 | E4: A | F4: 52 | G4: 0.00014126898 | H4: 0.99458992 | I4: C | J4: 156 | K4: =J4/SUM(J:J) -> 0.016160502 | L4: =K4+L3 -> 0.08018095 | M4: =IF(L4<0.8,"A",IF(L4<0.95,"B","C")) -> A | N4: =E4&I4&M4 -> ACA | O4: =VLOOKUP(A4,XYZ!A3:G806,2,FALSE) -> 0.61418152 | P4: =IF(O4<0.1,"A",IF(O4<0.25,"Y","Z")) -> Z | Q4: =N4&P4 -> ACAZ
A5: ВАЛИДОЛ 60МГ. №10 ТАБ. ПОДЪЯЗЫЧ. /ФАРМСТАНДАРТ/ | B5: 25 | C5: 0.02 | D5: 0.1 | E5: A | F5: 892 | G5: 0.0024233063 | H5: 0.46855501 | I5: A | J5: 150 | K5: =J5/SUM(J:J) -> 0.015538944 | L5: =K5+L4 -> 0.095719894 | M5: =IF(L5<0.8,"A",IF(L5<0.95,"B","C")) -> A | N5: =E5&I5&M5 -> AAA | O5: =VLOOKUP(A5,XYZ!A4:G807,2,FALSE) -> 0.70710678 | P5: =IF(O5<0.1,"A",IF(O5<0.25,"Y","Z")) -> Z | Q5: =N5&P5 -> AAAZ
A6: БОРНАЯ К-ТА 10Г. ДЕЗ.СР-ВО ПОР. (НДС 20%) | B6: 22 | C6: 0.01 | D6: 0.11 | E6: A | F6: 308 | G6: 0.00083674702 | H6: 0.823596 | I6: B | J6: 132 | K6: =J6/SUM(J:J) -> 0.013674271 | L6: =K6+L5 -> 0.10939416 | M6: =IF(L6<0.8,"A",IF(L6<0.95,"B","C")) -> A | N6: =E6&I6&M6 -> ABA | O6: =VLOOKUP(A6,XYZ!A5:G808,2,FALSE) -> 2.236068 | P6: =IF(O6<0.1,"A",IF(O6<0.25,"Y","Z")) -> Z | Q6: =N6&P6 -> ABAZ
A7: ГЕМАТОГЕН РУССКИЙ ДЕТСКИЙ 40Г. ПЛИТКА /ФАРМ-ПРО/ | B7: 17 | C7: 0.01 | D7: 0.12 | E7: A | F7: 289 | G7: 0.00078512951 | H7: 0.84067659 | I7: B | J7: 102 | K7: =J7/SUM(J:J) -> 0.010566482 | L7: =K7+L6 -> 0.11996065 | M7: =IF(L7<0.8,"A",IF(L7<0.95,"B","C")) -> A | N7: =E7&I7&M7 -> ABA | O7: =VLOOKUP(A7,XYZ!A6:G809,2,FALSE) -> 0.4460515 | P7: =IF(O7<0.1,"A",IF(O7<0.25,"Y","Z")) -> Z | Q7: =N7&P7 -> ABAZ
A8: КОРВАЛОЛ 25МЛ. КАПЛИ Д/ПРИЕМА ВНУТРЬ ФЛ. И/У /ФАРМСТАНДАРТ ЛЕКСРЕДСТВА/ | B8: 14 | C8: 0.01 | D8: 0.13 | E8: A | F8: 364 | G8: 0.00098888284 | H8: 0.78322078 | I8: A | J8: 84 | K8: =J8/SUM(J:J) -> 0.0087018086 | L8: =K8+L7 -> 0.12866246 | M8: =IF(L8<0.8,"A",IF(L8<0.95,"B","C")) -> A | N8: =E8&I8&M8 -> AAA | O8: =VLOOKUP(A8,XYZ!A7:G810,2,FALSE) -> 0.85266688 | P8: =IF(O8<0.1,"A",IF(O8<0.25,"Y","Z")) -> Z | Q8: =N8&P8 -> AAAZ
A9: ЛЕЙКОПЛАСТЫРЬ БАКТЕР. 4Х10 №1 /ВЕРОФАРМ/ | B9: 14 | C9: 0.01 | D9: 0.14 | E9: A | F9: 126 | G9: 0.0003423056 | H9: 0.9543221 | I9: C | J9: 84 | K9: =J9/SUM(J:J) -> 0.0087018086 | L9: =K9+L8 -> 0.13736426 | M9: =IF(L9<0.8,"A",IF(L9<0.95,"B","C")) -> A | N9: =E9&I9&M9 -> ACA | O9: =VLOOKUP(A9,XYZ!A8:G811,2,FALSE) -> 1.5649216 | P9: =IF(O9<0.1,"A",IF(O9<0.25,"Y","Z")) -> Z | Q9: =N9&P9 -> ACAZ
A10: РАУНАТИН 2МГ. №50 ТАБ. П/О /ЗДОРОВЬЕ/ | B10: 13 | C10: 0.01 | D10: 0.17 | E10: A | F10: 1673 | G10: 0.0045450577 | H10: 0.24991442 | I10: A | J10: 78 | K10: =J10/SUM(J:J) -> 0.0080802508 | L10: =K10+L9 -> 0.14544451 | M10: =IF(L10<0.8,"A",IF(L10<0.95,"B","C")) -> A | N10: =E10&I10&M10 -> AAA | O10: =VLOOKUP(A10,XYZ!A9:G812,2,FALSE) -> 2.236068 | P10: =IF(O10<0.1,"A",IF(O10<0.25,"Y","Z")) -> Z | Q10: =N10&P10 -> AAAZ
A11: МЕНОВАЗИН 40МЛ. №1 СПИРТ. Р-Р Д/НАРУЖ.ПРИМ. ФЛ. /САМАРАМЕДПРОМ/ | B11: 13 | C11: 0.01 | D11: 0.15 | E11: A | F11: 468 | G11: 0.0012714208 | H11: 0.6943465 | I11: A | J11: 78 | K11: =J11/SUM(J:J) -> 0.0080802508 | L11: =K11+L10 -> 0.15352477 | M11: =IF(L11<0.8,"A",IF(L11<0.95,"B","C")) -> A | N11: =E11&I11&M11 -> AAA | O11: =VLOOKUP(A11,XYZ!A10:G813,2,FALSE) -> 1.0029542 | P11: =IF(O11<0.1,"A",IF(O11<0.25,"Y","Z")) -> Z | Q11: =N11&P11 -> AAAZ
A12: ПЕРЕКИСЬ ВОДОРОДА 3% 100МЛ. №1 Р-Р ДЕЗ.СР-ВО ФЛ. (НДС 20%) | B12: 13 | C12: 0.01 | D12: 0.16 | E12: A | F12: 221 | G12: 0.00060039316 | H12: 0.89687121 | I12: B | J12: 78 | K12: =J12/SUM(J:J) -> 0.0080802508 | L12: =K12+L11 -> 0.16160502 | M12: =IF(L12<0.8,"A",IF(L12<0.95,"B","C")) -> A | N12: =E12&I12&M12 -> ABA | O12: =VLOOKUP(A12,XYZ!A11:G814,2,FALSE) -> 0.88545111 | P12: =IF(O12<0.1,"A",IF(O12<0.25,"Y","Z")) -> Z | Q12: =N12&P12 -> ABAZ
A13: ЛЕЙКОПЛАСТЫРЬ БАКТЕР. 6X10 №1 /ВЕРОФАРМ/ | B13: 13 | C13: 0.01 | D13: 0.15 | E13: A | F13: 104 | G13: 0.00028253796 | H13: 0.96752165 | I13: C | J13: 78 | K13: =J13/SUM(J:J) -> 0.0080802508 | L13: =K13+L12 -> 0.16968527 | M13: =IF(L13<0.8,"A",IF(L13<0.95,"B","C")) -> A | N13: =E13&I13&M13 -> ACA | O13: =VLOOKUP(A13,XYZ!A12:G815,2,FALSE) -> 1.6676526 | P13: =IF(O13<0.1,"A",IF(O13<0.25,"Y","Z")) -> Z | Q13: =N13&P13 -> ACAZ
A14: Карта LOYALITY 0,01Р | B14: 12 | C14: 0.01 | D14: 0.18 | E14: A | F14: 0.12 | G14: 3.2600533e-07 | H14: 1 | I14: C | J14: 72 | K14: =J14/SUM(J:J) -> 0.007458693 | L14: =K14+L13 -> 0.17714396 | M14: =IF(L14<0.8,"A",IF(L14<0.95,"B","C")) -> A | N14: =E14&I14&M14 -> ACA | O14: =VLOOKUP(A14,XYZ!A13:G816,2,FALSE) -> 0.372678 | P14: =IF(O14<0.1,"A",IF(O14<0.25,"Y","Z")) -> Z | Q14: =N14&P14 -> ACAZ
... A804: ХАРТМАНН КОСМОПОР Е ПОВЯЗКА 7,2Х5СМ №50 П/ОПЕР. САМОКЛ. СТЕР. /АРТ.9008705/ [HARTMANN COSMOPOR] | B804: 0.04 | C804: 0 | D804: 1 | E804: C | F804: 25.8 | G804: 7.0091147e-05 | H804: 0.99952697 | I804: C | J804: 0.24 | K804: =J804/SUM(J:J) -> 2.486231e-05 | L804: =K804+L803 -> 1 | M804: =IF(L804<0.8,"A",IF(L804<0.95,"B","C")) -> C | N804: =E804&I804&M804 -> CCC | O804: =VLOOKUP(A804,XYZ!A803:G1606,2,FALSE) -> 2.236068 | P804: =IF(O804<0.1,"A",IF(O804<0.25,"Y","Z")) -> Z | Q804: =N804&P804 -> CCCZ

Sheet XYZ
A1: Название | B1: VAR | C1: 44774 | D1: 44775 | E1: 44776 | F1: 44777 | G1: 44778
A2: ЛЕЙКОПЛАСТЫРЬ БАКТЕР. 2,5Х7,2 №1 /ВЕРОФАРМ/ | B2: =_xlfn.STDEV.S(C2:G2)/AVERAGE(C2:G2) -> 0.89693828 | C2: =SUMIFS('data (1)'!$M:$M,'data (1)'!$A:$A,XYZ!C$1,'data (1)'!$J:$J,XYZ!$A2) -> 24 | D2: =SUMIFS('data (1)'!$M:$M,'data (1)'!$A:$A,XYZ!D$1,'data (1)'!$J:$J,XYZ!$A2) -> 0 | E2: =SUMIFS('data (1)'!$M:$M,'data (1)'!$A:$A,XYZ!E$1,'data (1)'!$J:$J,XYZ!$A2) -> 4 | F2: =SUMIFS('data (1)'!$M:$M,'data (1)'!$A:$A,XYZ!F$1,'data (1)'!$J:$J,XYZ!$A2) -> 12 | G2: =SUMIFS('data (1)'!$M:$M,'data (1)'!$A:$A,XYZ!G$1,'data (1)'!$J:$J,XYZ!$A2) -> 28
A3: НАФТИЗИН 0,1% 15МЛ. НАЗАЛ.КАПЛИ ФЛ./КАП. /СЛАВЯНСКАЯ АПТЕКА/ | B3: =_xlfn.STDEV.S(C3:G3)/AVERAGE(C3:G3) -> 0.69985421 | C3: =SUMIFS('data (1)'!$M:$M,'data (1)'!$A:$A,XYZ!C$1,'data (1)'!$J:$J,XYZ!$A3) -> 2 | D3: =SUMIFS('data (1)'!$M:$M,'data (1)'!$A:$A,XYZ!D$1,'data (1)'!$J:$J,XYZ!$A3) -> 10 | E3: =SUMIFS('data (1)'!$M:$M,'data (1)'!$A:$A,XYZ!E$1,'data (1)'!$J:$J,XYZ!$A3) -> 5 | F3: =SUMIFS('data (1)'!$M:$M,'data (1)'!$A:$A,XYZ!F$1,'data (1)'!$J:$J,XYZ!$A3) -> 4 | G3: =SUMIFS('data (1)'!$M:$M,'data (1)'!$A:$A,XYZ!G$1,'data (1)'!$J:$J,XYZ!$A3) -> 14
A4: ПАКЕТ | B4: =_xlfn.STDEV.S(C4:G4)/AVERAGE(C4:G4) -> 0.61418152 | C4: =SUMIFS('data (1)'!$M:$M,'data (1)'!$A:$A,XYZ!C$1,'data (1)'!$J:$J,XYZ!$A4) -> 10 | D4: =SUMIFS('data (1)'!$M:$M,'data (1)'!$A:$A,XYZ!D$1,'data (1)'!$J:$J,XYZ!$A4) -> 3 | E4: =SUMIFS('data (1)'!$M:$M,'data (1)'!$A:$A,XYZ!E$1,'data (1)'!$J:$J,XYZ!$A4) -> 3 | F4: =SUMIFS('data (1)'!$M:$M,'data (1)'!$A:$A,XYZ!F$1,'data (1)'!$J:$J,XYZ!$A4) -> 3 | G4: =SUMIFS('data (1)'!$M:$M,'data (1)'!$A:$A,XYZ!G$1,'data (1)'!$J:$J,XYZ!$A4) -> 7
A5: ВАЛИДОЛ 60МГ. №10 ТАБ. ПОДЪЯЗЫЧ. /ФАРМСТАНДАРТ/ | B5: =_xlfn.STDEV.S(C5:G5)/AVERAGE(C5:G5) -> 0.70710678 | C5: =SUMIFS('data (1)'!$M:$M,'data (1)'!$A:$A,XYZ!C$1,'data (1)'!$J:$J,XYZ!$A5) -> 2 | D5: =SUMIFS('data (1)'!$M:$M,'data (1)'!$A:$A,XYZ!D$1,'data (1)'!$J:$J,XYZ!$A5) -> 5 | E5: =SUMIFS('data (1)'!$M:$M,'data (1)'!$A:$A,XYZ!E$1,'data (1)'!$J:$J,XYZ!$A5) -> 4 | F5: =SUMIFS('data (1)'!$M:$M,'data (1)'!$A:$A,XYZ!F$1,'data (1)'!$J:$J,XYZ!$A5) -> 11 | G5: =SUMIFS('data (1)'!$M:$M,'data (1)'!$A:$A,XYZ!G$1,'data (1)'!$J:$J,XYZ!$A5) -> 3
A6: БОРНАЯ К-ТА 10Г. ДЕЗ.СР-ВО ПОР. (НДС 20%) | B6: =_xlfn.STDEV.S(C6:G6)/AVERAGE(C6:G6) -> 2.236068 | C6: =SUMIFS('data (1)'!$M:$M,'data (1)'!$A:$A,XYZ!C$1,'data (1)'!$J:$J,XYZ!$A6) -> 0 | D6: =SUMIFS('data (1)'!$M:$M,'data (1)'!$A:$A,XYZ!D$1,'data (1)'!$J:$J,XYZ!$A6) -> 22 | E6: =SUMIFS('data (1)'!$M:$M,'data (1)'!$A:$A,XYZ!E$1,'data (1)'!$J:$J,XYZ!$A6) -> 0 | F6: =SUMIFS('data (1)'!$M:$M,'data (1)'!$A:$A,XYZ!F$1,'data (1)'!$J:$J,XYZ!$A6) -> 0 | G6: =SUMIFS('data (1)'!$M:$M,'data (1)'!$A:$A,XYZ!G$1,'data (1)'!$J:$J,XYZ!$A6) -> 0
A7: ГЕМАТОГЕН РУССКИЙ ДЕТСКИЙ 40Г. ПЛИТКА /ФАРМ-ПРО/ | B7: =_xlfn.STDEV.S(C7:G7)/AVERAGE(C7:G7) -> 0.4460515 | C7: =SUMIFS('data (1)'!$M:$M,'data (1)'!$A:$A,XYZ!C$1,'data (1)'!$J:$J,XYZ!$A7) -> 3 | D7: =SUMIFS('data (1)'!$M:$M,'data (1)'!$A:$A,XYZ!D$1,'data (1)'!$J:$J,XYZ!$A7) -> 3 | E7: =SUMIFS('data (1)'!$M:$M,'data (1)'!$A:$A,XYZ!E$1,'data (1)'!$J:$J,XYZ!$A7) -> 6 | F7: =SUMIFS('data (1)'!$M:$M,'data (1)'!$A:$A,XYZ!F$1,'data (1)'!$J:$J,XYZ!$A7) -> 3 | G7: =SUMIFS('data (1)'!$M:$M,'data (1)'!$A:$A,XYZ!G$1,'data (1)'!$J:$J,XYZ!$A7) -> 2
A8: КОРВАЛОЛ 25МЛ. КАПЛИ Д/ПРИЕМА ВНУТРЬ ФЛ. И/У /ФАРМСТАНДАРТ ЛЕКСРЕДСТВА/ | B8: =_xlfn.STDEV.S(C8:G8)/AVERAGE(C8:G8) -> 0.85266688 | C8: =SUMIFS('data (1)'!$M:$M,'data (1)'!$A:$A,XYZ!C$1,'data (1)'!$J:$J,XYZ!$A8) -> 4 | D8: =SUMIFS('data (1)'!$M:$M,'data (1)'!$A:$A,XYZ!D$1,'data (1)'!$J:$J,XYZ!$A8) -> 0 | E8: =SUMIFS('data (1)'!$M:$M,'data (1)'!$A:$A,XYZ!E$1,'data (1)'!$J:$J,XYZ!$A8) -> 6 | F8: =SUMIFS('data (1)'!$M:$M,'data (1)'!$A:$A,XYZ!F$1,'data (1)'!$J:$J,XYZ!$A8) -> 3 | G8: =SUMIFS('data (1)'!$M:$M,'data (1)'!$A:$A,XYZ!G$1,'data (1)'!$J:$J,XYZ!$A8) -> 1
A9: ЛЕЙКОПЛАСТЫРЬ БАКТЕР. 4Х10 №1 /ВЕРОФАРМ/ | B9: =_xlfn.STDEV.S(C9:G9)/AVERAGE(C9:G9) -> 1.5649216 | C9: =SUMIFS('data (1)'!$M:$M,'data (1)'!$A:$A,XYZ!C$1,'data (1)'!$J:$J,XYZ!$A9) -> 0 | D9: =SUMIFS('data (1)'!$M:$M,'data (1)'!$A:$A,XYZ!D$1,'data (1)'!$J:$J,XYZ!$A9) -> 0 | E9: =SUMIFS('data (1)'!$M:$M,'data (1)'!$A:$A,XYZ!E$1,'data (1)'!$J:$J,XYZ!$A9) -> 0 | F9: =SUMIFS('data (1)'!$M:$M,'data (1)'!$A:$A,XYZ!F$1,'data (1)'!$J:$J,XYZ!$A9) -> 10 | G9: =SUMIFS('data (1)'!$M:$M,'data (1)'!$A:$A,XYZ!G$1,'data (1)'!$J:$J,XYZ!$A9) -> 4
A10: РАУНАТИН 2МГ. №50 ТАБ. П/О /ЗДОРОВЬЕ/ | B10: =_xlfn.STDEV.S(C10:G10)/AVERAGE(C10:G10) -> 2.236068 | C10: =SUMIFS('data (1)'!$M:$M,'data (1)'!$A:$A,XYZ!C$1,'data (1)'!$J:$J,XYZ!$A10) -> 0 | D10: =SUMIFS('data (1)'!$M:$M,'data (1)'!$A:$A,XYZ!D$1,'data (1)'!$J:$J,XYZ!$A10) -> 0 | E10: =SUMIFS('data (1)'!$M:$M,'data (1)'!$A:$A,XYZ!E$1,'data (1)'!$J:$J,XYZ!$A10) -> 0 | F10: =SUMIFS('data (1)'!$M:$M,'data (1)'!$A:$A,XYZ!F$1,'data (1)'!$J:$J,XYZ!$A10) -> 0 | G10: =SUMIFS('data (1)'!$M:$M,'data (1)'!$A:$A,XYZ!G$1,'data (1)'!$J:$J,XYZ!$A10) -> 13
A11: МЕНОВАЗИН 40МЛ. №1 СПИРТ. Р-Р Д/НАРУЖ.ПРИМ. ФЛ. /САМАРАМЕДПРОМ/ | B11: =_xlfn.STDEV.S(C11:G11)/AVERAGE(C11:G11) -> 1.0029542 | C11: =SUMIFS('data (1)'!$M:$M,'data (1)'!$A:$A,XYZ!C$1,'data (1)'!$J:$J,XYZ!$A11) -> 4 | D11: =SUMIFS('data (1)'!$M:$M,'data (1)'!$A:$A,XYZ!D$1,'data (1)'!$J:$J,XYZ!$A11) -> 6 | E11: =SUMIFS('data (1)'!$M:$M,'data (1)'!$A:$A,XYZ!E$1,'data (1)'!$J:$J,XYZ!$A11) -> 3 | F11: =SUMIFS('data (1)'!$M:$M,'data (1)'!$A:$A,XYZ!F$1,'data (1)'!$J:$J,XYZ!$A11) -> 0 | G11: =SUMIFS('data (1)'!$M:$M,'data (1)'!$A:$A,XYZ!G$1,'data (1)'!$J:$J,XYZ!$A11) -> 0
A12: ПЕРЕКИСЬ ВОДОРОДА 3% 100МЛ. №1 Р-Р ДЕЗ.СР-ВО ФЛ. (НДС 20%) | B12: =_xlfn.STDEV.S(C12:G12)/AVERAGE(C12:G12) -> 0.88545111 | C12: =SUMIFS('data (1)'!$M:$M,'data (1)'!$A:$A,XYZ!C$1,'data (1)'!$J:$J,XYZ!$A12) -> 0 | D12: =SUMIFS('data (1)'!$M:$M,'data (1)'!$A:$A,XYZ!D$1,'data (1)'!$J:$J,XYZ!$A12) -> 5 | E12: =SUMIFS('data (1)'!$M:$M,'data (1)'!$A:$A,XYZ!E$1,'data (1)'!$J:$J,XYZ!$A12) -> 2 | F12: =SUMIFS('data (1)'!$M:$M,'data (1)'!$A:$A,XYZ!F$1,'data (1)'!$J:$J,XYZ!$A12) -> 1 | G12: =SUMIFS('data (1)'!$M:$M,'data (1)'!$A:$A,XYZ!G$1,'data (1)'!$J:$J,XYZ!$A12) -> 5
A13: ЛЕЙКОПЛАСТЫРЬ БАКТЕР. 6X10 №1 /ВЕРОФАРМ/ | B13: =_xlfn.STDEV.S(C13:G13)/AVERAGE(C13:G13) -> 1.6676526 | C13: =SUMIFS('data (1)'!$M:$M,'data (1)'!$A:$A,XYZ!C$1,'data (1)'!$J:$J,XYZ!$A13) -> 10 | D13: =SUMIFS('data (1)'!$M:$M,'data (1)'!$A:$A,XYZ!D$1,'data (1)'!$J:$J,XYZ!$A13) -> 0 | E13: =SUMIFS('data (1)'!$M:$M,'data (1)'!$A:$A,XYZ!E$1,'data (1)'!$J:$J,XYZ!$A13) -> 0 | F13: =SUMIFS('data (1)'!$M:$M,'data (1)'!$A:$A,XYZ!F$1,'data (1)'!$J:$J,XYZ!$A13) -> 3 | G13: =SUMIFS('data (1)'!$M:$M,'data (1)'!$A:$A,XYZ!G$1,'data (1)'!$J:$J,XYZ!$A13) -> 0
... A804: ХАРТМАНН КОСМОПОР Е ПОВЯЗКА 7,2Х5СМ №50 П/ОПЕР. САМОКЛ. СТЕР. /АРТ.9008705/ [HARTMANN COSMOPOR] | B804: =_xlfn.STDEV.S(C804:G804)/AVERAGE(C804:G804) -> 2.236068 | C804: =SUMIFS('data (1)'!$M:$M,'data (1)'!$A:$A,XYZ!C$1,'data (1)'!$J:$J,XYZ!$A804) -> 0 | D804: =SUMIFS('data (1)'!$M:$M,'data (1)'!$A:$A,XYZ!D$1,'data (1)'!$J:$J,XYZ!$A804) -> 0 | E804: =SUMIFS('data (1)'!$M:$M,'data (1)'!$A:$A,XYZ!E$1,'data (1)'!$J:$J,XYZ!$A804) -> 0 | F804: =SUMIFS('data (1)'!$M:$M,'data (1)'!$A:$A,XYZ!F$1,'data (1)'!$J:$J,XYZ!$A804) -> 0.04 | G804: =SUMIFS('data (1)'!$M:$M,'data (1)'!$A:$A,XYZ!G$1,'data (1)'!$J:$J,XYZ!$A804) -> 0
